Workbook

Sheet 入力
E2: 入 力 シ ー ト
C4: ：必要箇所を入力して下さい | H4: 調査士名 | I4: 山本真基
H5: 業務番号 | I5: Y2026-018
C6: ：選択して下さい | H6: 源泉所得税 | I6: なし
H7: 見積日 | I7: 46036
C8: ：緑色の表内で該当する数字を入力して下さい | H8: 請求日 | I8: 46058
H9: 領収日 | I9: 46080
C10: ：入力不可 | H10: 宛名上段
H11: 宛名下段 | I11: 玉腰裕規様、明日野様
H12: 請求額 | I12: =H65 -> 133870
A13: 所 在 | E13: 浜松中央区初生町822番20、822番23、822番25
A14: 受 託 内 容 | E14: 建物表題登記
A15: 作 業 種 別 | E15: 数 量 | F15: 基 準 額 | G15: 加減率等 | H15: 報 酬 額 | I15: 摘 要
A16: 調査業務 | B16: 資料 | C16: 公簿類 | E16: 3 | F16: 1100 | G16: 100 | H16: =IF(E16="","",E16*F16*G16/100) -> 3300
C17: 地図類 | E17: 1 | F17: 1100 | G17: 100 | H17: =IF(E17="","",E17*F17*G17/100) -> 1100
C18: 図面類 | E18: 3 | F18: 1100 | G18: 100 | H18: =IF(E18="","",E18*F18*G18/100) -> 3300
C19: 疎明書面 | E19: 1 | F19: 6000 | G19: 100 | H19: =IF(E19="","",E19*F19*G19/100) -> 6000
B20: 現 地 | C20: 確認 | F20: 8000 | G20: 100 | H20: =IF(E20="","",E20*F20*G20/100) | I20: 敷地境界が不明な場合の調査
C21: 探索 | F21: 10000 | G21: 100 | H21: =IF(E21="","",E21*F21*G21/100) | I21: 敷地境界が不明な場合の調査
C22: 多角測量 | F22: 15000 | G22: 100 | H22: =IF(E22="","",E22*F22*G22/100) | I22: 敷地境界が不明な場合の調査
G23: 小 計 | H23: =SUM(H16:H22) -> 13700
A24: 測量業務 | B24: 面積測量 | D24: 3 | E24: 110 | F24: =IF(D24="","",VLOOKUP(D24,$K$25:$M$34,3)) -> 40000 | G24: 100 | H24: =IF(D24="","",F24*G24/100) -> 40000 | K24: 床面積別基準額リスト
F25: =IF(D25="","",VLOOKUP(D25,$K$25:$M$34,3)) | G25: 100 | H25: =IF(D25="","",F25*G25/100) | K25: 1 | L25: 50㎡以下 | M25: 25000
F26: =IF(D26="","",VLOOKUP(D26,$K$25:$M$34,3)) | G26: 100 | H26: =IF(D26="","",F26*G26/100) | K26: 2 | L26: 100㎡以下 | M26: 32000
F27: =IF(D27="","",VLOOKUP(D27,$K$25:$M$34,3)) | G27: 100 | H27: =IF(D27="","",F27*G27/100) | K27: 3 | L27: 200㎡以下 | M27: 40000
G28: 小 計 | H28: =SUM(H24:H27) -> 40000 | K28: 4 | L28: 300㎡以下 | M28: 48000
A29: 登記申請業務 | B29: 表題 | D29: 基本 | E29: 1 | F29: 25000 | G29: 100 | H29: =IF(E29+E30+E31=0,"",(E29*F29+E30*F30+E31*F31)*G29/100) -> 30000 | I29: 1棟1階 | K29: 5 | L29: 400㎡以下 | M29: 55000
D30: 加算 | F30: 6000 | I30: 附属建物1棟1階増加ごと | K30: 6 | L30: 600㎡以下 | M30: 62000
D31: 加算 | E31: 1 | F31: 5000 | I31: 1階増加ごと | K31: 7 | L31: 800㎡以下 | M31: 73000
B32: 表示変更・更正 | D32: 基本 | F32: 25000 | G32: 100 | H32: =IF(E32+E33+E34=0,"",(E32*F32+E33*F33+E34*F34)*G32/100) | I32: 1棟1階 | K32: 8 | L32: 1000㎡以下 | M32: 80000
D33: 加算 | F33: 6000 | I33: 附属建物1棟1階増加ごと | K33: 9 | L33: 2000㎡以下 | M33: 120000
D34: 加算 | F34: 5000 | I34: 1階増加ごと | K34: 10 | L34: 3000㎡以下 | M34: 140000
B35: 表示変更・更正 （図面不要） | D35: 基本 | F35: 20000 | G35: 100 | H35: =IF(E35+E36=0,"",(E35*F35+E36*F36)*G35/100) | I35: 1棟 | K35: 11 | L35: 4000 | M35: 155000
D36: 加算 | F36: 1000 | I36: 附属建物1棟増加ごと | K36: 12 | L36: 5000 | M36: =ROUNDDOWN(M35+((L36-L35)/1000)*15000,-3) -> 170000 | N36: ←4000㎡超の場合面積記入
B37: 滅失 | D37: 基本 | F37: 20000 | G37: 100 | H37: =IF(E37+E38=0,"",(E37*F37+E38*F38)*G37/100) | I37: 1棟 | K37: 面積加減率
D38: 加算 | F38: 1000 | I38: 附属建物1棟増加ごと | L38: 4区画まで | M38: 100％
D39: 基本 | F39: 15000 | G39: 100 | H39: =IF(E39+E40+E41+E42+E43=0,"",(E39*F39+E40*F40+E41*F41+E42*F42+E43*F43)*G39/100) | L39: 5～7区画 | M39: 120％
D40: 加算 | L40: 8～10区画 | M40: 140％
D41: 加算
D42: 加算
...

Sheet 見積書
A7: =IF(入力!I10="","",入力!I10) | G7: =IF(入力!I7="","",入力!I7) -> 46036
A9: =IF(入力!I11="","",入力!I11) -> 玉腰裕規様、明日野様 | G9: 事務所 豊橋市前田南町一丁目1番地5
B10: 下記のとおり御見積いたします。 | G10: ﾀﾜｰﾚｼﾞﾃﾞﾝｽｱﾈｯｸｽ2-2E
B11: =入力!I12 -> 133870 | G11: =入力!I4 -> 山本真基
A12: 所 在 | E12: =IF(入力!E13="","",入力!E13) -> 浜松中央区初生町822番20、822番23、822番25
A13: 受 託 内 容 | E13: =IF(入力!E14="","",入力!E14) -> 建物表題登記
A14: 作 業 種 別 | E14: 数 量 | F14: 基 準 額 | G14: 加減率等 | H14: 報 酬 額 | I14: 摘 要
A15: 調査業務 | B15: 資料 | C15: 公簿類 | E15: =IF(入力!E16="","",入力!E16) -> 3 | F15: =入力!F16 -> 1100 | G15: =IF(入力!E16="","",入力!G16) -> 100 | H15: =入力!H16 -> 3300 | I15: =IF(入力!I16="","",入力!I16)
C16: 地図類 | E16: =IF(入力!E17="","",入力!E17) -> 1 | F16: =入力!F17 -> 1100 | G16: =IF(入力!E17="","",入力!G17) -> 100 | H16: =入力!H17 -> 1100 | I16: =IF(入力!I17="","",入力!I17)
C17: 図面類 | E17: =IF(入力!E18="","",入力!E18) -> 3 | F17: =入力!F18 -> 1100 | G17: =IF(入力!E18="","",入力!G18) -> 100 | H17: =入力!H18 -> 3300 | I17: =IF(入力!I18="","",入力!I18)
C18: 疎明書面 | E18: =IF(入力!E19="","",入力!E19) -> 1 | F18: =入力!F19 -> 6000 | G18: =IF(入力!E19="","",入力!G19) -> 100 | H18: =入力!H19 -> 6000 | I18: =IF(入力!I19="","",入力!I19)
B19: 現 地 | C19: 確認 | E19: =IF(入力!E20="","",入力!E20) | F19: =入力!F20 -> 8000 | G19: =IF(入力!E20="","",入力!G20) | H19: =入力!H20 | I19: =IF(入力!I20="","",入力!I20) -> 敷地境界が不明な場合の調査
C20: 探索 | E20: =IF(入力!E21="","",入力!E21) | F20: =入力!F21 -> 10000 | G20: =IF(入力!E21="","",入力!G21) | H20: =入力!H21 | I20: =IF(入力!I21="","",入力!I21) -> 敷地境界が不明な場合の調査
C21: 多角測量 | E21: =IF(入力!E22="","",入力!E22) | F21: 15000 | G21: =IF(入力!E22="","",入力!G22) | H21: =入力!H22 | I21: =IF(入力!I22="","",入力!I22) -> 敷地境界が不明な場合の調査
G22: 小 計 | H22: =入力!H23 -> 13700 | I22: =IF(入力!I23="","",入力!I23)
A23: 測量業務 | B23: =IF(入力!B24="","",入力!B24) -> 面積測量 | E23: =IF(入力!E24="","",入力!E24) -> 110 | F23: =入力!F24 -> 40000 | G23: =IF(入力!E24="","",入力!G24) -> 100 | H23: =入力!H24 -> 40000 | I23: =IF(入力!I24="","",入力!I24)
B24: =IF(入力!B25="","",入力!B25) | E24: =IF(入力!E25="","",入力!E25) | F24: =入力!F25 | G24: =IF(入力!E25="","",入力!G25) | H24: =入力!H25 | I24: =IF(入力!I25="","",入力!I25)
B25: =IF(入力!B26="","",入力!B26) | E25: =IF(入力!E26="","",入力!E26) | F25: =入力!F26 | G25: =IF(入力!E26="","",入力!G26) | H25: =入力!H26 | I25: =IF(入力!I26="","",入力!I26)
B26: =IF(入力!B27="","",入力!B27) | E26: =IF(入力!E27="","",入力!E27) | F26: =入力!F27 | G26: =IF(入力!E27="","",入力!G27) | H26: =入力!H27 | I26: =IF(入力!I27="","",入力!I27)
G27: 小 計 | H27: =入力!H28 -> 40000 | I27: =IF(入力!I28="","",入力!I28)
A28: 登記申請業務 | B28: =入力!B29 -> 表題 | D28: 基本 | E28: =IF(入力!E29="","",入力!E29) -> 1 | F28: =入力!F29 -> 25000 | G28: =IF(入力!E29+入力!E30+入力!E31=0,"",入力!G29) -> 100 | H28: =入力!H29 -> 30000 | I28: =IF(入力!I29="","",入力!I29) -> 1棟1階
D29: 加算 | E29: =IF(入力!E30="","",入力!E30) | F29: =入力!F30 -> 6000 | I29: =IF(入力!I30="","",入力!I30) -> 附属建物1棟1階増加ごと
D30: 加算 | E30: =IF(入力!E31="","",入力!E31) -> 1 | F30: =入力!F31 -> 5000 | I30: =IF(入力!I31="","",入力!I31) -> 1階増加ごと
B31: =入力!B32 -> 表示変更・更正 | D31: 基本 | E31: =IF(入力!E32="","",入力!E32) | F31: =入力!F32 -> 25000 | G31: =IF(入力!E32+入力!E33+入力!E34=0,"",入力!G32) | H31: =入力!H32 | I31: =IF(入力!I32="","",入力!I32) -> 1棟1階
D32: 加算 | E32: =IF(入力!E33="","",入力!E33) | F32: =入力!F33 -> 6000 | I32: =IF(入力!I33="","",入力!I33) -> 附属建物1棟1階増加ごと
D33: 加算 | E33: =IF(入力!E34="","",入力!E34) | F33: =入力!F34 -> 5000 | I33: =IF(入力!I34="","",入力!I34) -> 1階増加ごと
B34: =入力!B35 -> 表示変更・更正 （図面不要） | D34: 基本 | E34: =IF(入力!E35="","",入力!E35) | F34: =入力!F35 -> 20000 | G34: =IF(入力!E35+入力!E36=0,"",入力!G35) | H34: =入力!H35 | I34: =IF(入力!I35="","",入力!I35) -> 1棟
D35: 加算 | E35: =IF(入力!E36="","",入力!E36) | F35: =入力!F36 -> 1000 | I35: =IF(入力!I36="","",入力!I36) -> 附属建物1棟増加ごと
B36: =入力!B37 -> 滅失 | D36: 基本 | E36: =IF(入力!E37="","",入力!E37) | F36: =入力!F37 -> 20000 | G36: =IF(入力!E37+入力!E38=0,"",入力!G37) | H36: =入力!H37 | I36: =IF(入力!I37="","",入力!I37) -> 1棟
D37: 加算 | E37: =IF(入力!E38="","",入力!E38) | F37: =入力!F38 -> 1000 | I37: =IF(入力!I38="","",入力!I38) -> 附属建物1棟増加ごと
B38: =IF(入力!B39="","",入力!B39) | D38: 基本 | E38: =IF(入力!E39="","",入力!E39) | F38: =入力!F39 -> 15000 | G38: =IF(入力!E39+入力!E40+入力!E41+入力!E42+入力!E43=0,"",入力!G39) | H38: =入力!H39 | I38: =IF(入力!I39="","",入力!I39)
D39: 加算 | E39: =IF(入力!E40="","",入力!E40) | F39: =入力!F40 -> 0 | I39: =IF(入力!I40="","",入力!I40)
D40: 加算 | E40: =IF(入力!E41="","",入力!E41) | F40: =入力!F41 -> 0 | I40: =IF(入力!I41="","",入力!I41)
D41: 加算 | E41: =IF(入力!E42="","",入力!E42) | F41: =入力!F42 -> 0 | I41: =IF(入力!I42="","",入力!I42)
D42: 加算 | E42: =IF(入力!E43="","",入力!E43) | F42: =入力!F43 -> 0 | I42: =IF(入力!I43="","",入力!I43)
B43: =入力!B44 -> 現地調査費 | E43: =IF(入力!E44="","",入力!E44) -> 1 | F43: =入力!F44 -> 18000 | G43: =IF(入力!E44="","",入力!G44) -> 100 | H43: =入力!H44 -> 18000 | I43: =IF(入力!I44="","",入力!I44)
G44: 小 計 | H44: =入力!H45 -> 48000 | I44: =IF(入力!I45="","",入力!I45)
A45: 書類作成等 | B45: =入力!B46 -> 調査報告書 | E45: =IF(入力!E46="","",入力!E46) -> 1 | F45: =入力!F46 -> 6000 | G45: =IF(入力!E46="","",入力!G46) -> 100 | H45: =入力!H46 -> 6000 | I45: =IF(入力!I46="","",入力!I46)
B46: =入力!B47 -> 原本の複製 | E46: =IF(入力!E47="","",入力!E47) -> 4 | F46: =入力!F47 -> 1000 | G46: =IF(入力!E47="","",入力!G47) -> 100 | H46: =入力!H47 -> 4000 | I46: =IF(入力!I47="","",入力!I47)
B47: =入力!B48 -> 工事完了引渡証明 | E47: =IF(入力!E48="","",入力!E48) -> 1 | F47: =入力!F48 -> 5000 | G47: =IF(入力!E48="","",入力!G48) -> 100 | H47: =入力!H48 -> 5000 | I47: =IF(入力!I48="","",入力!I48)
...

Sheet 請求書
I1: お振込みは下記口座へお願いします
I2: 三菱ＵＦＪ銀行 豊橋支店
I3: =IF(入力!I4="青山紘一","普 通 ４７２２０４９",IF(入力!I4="青山貴洋","普 通 ５２８２４０７",IF(入力!I4="山本真基","普 通 ０４２１４２８"))) -> 普 通 ０４２１４２８
I4: =IF(入力!I4="青山紘一","ﾄﾁｶｵｸﾁｮｳｻｼ ｱｵﾔﾏｺｳｲﾁ",IF(入力!I4="青山貴洋","ﾄﾁｶｵｸﾁｮｳｻｼ ｱｵﾔﾏﾀｶﾋﾛ",IF(入力!I4="山本真基","ｷﾞｮｳｾｲｼｮｼ ﾔﾏﾓﾄﾏｻｷ"))) -> ｷﾞｮｳｾｲｼｮｼ ﾔﾏﾓﾄﾏｻｷ
I5: =IF(入力!I4="青山紘一","土地家屋調査士 青山紘一",IF(入力!I4="青山貴洋","土地家屋調査士 青山貴洋",IF(入力!I4="山本真基","行 政 書 士 山本 真基"))) -> 行 政 書 士 山本 真基
A7: =IF(入力!I10="","",入力!I10) | G7: =IF(入力!I8="","",入力!I8) -> 46058
A9: =IF(入力!I11="","",入力!I11) -> 玉腰裕規様、明日野様 | G9: 事務所 豊橋市前田南町一丁目1番地5
B10: 下記のとおり御請求いたします。 | G10: ﾀﾜｰﾚｼﾞﾃﾞﾝｽｱﾈｯｸｽ2-2E
B11: =入力!I12 -> 133870 | G11: =入力!I4 -> 山本真基
A12: 所 在 | E12: =IF(入力!E13="","",入力!E13) -> 浜松中央区初生町822番20、822番23、822番25
A13: 受 託 内 容 | E13: =IF(入力!E14="","",入力!E14) -> 建物表題登記
A14: 作 業 種 別 | E14: 数 量 | F14: 基 準 額 | G14: 加減率等 | H14: 報 酬 額 | I14: 摘 要
A15: 調査業務 | B15: 資料 | C15: 公簿類 | E15: =IF(入力!E16="","",入力!E16) -> 3 | F15: =入力!F16 -> 1100 | G15: =IF(入力!E16="","",入力!G16) -> 100 | H15: =入力!H16 -> 3300 | I15: =IF(入力!I16="","",入力!I16)
C16: 地図類 | E16: =IF(入力!E17="","",入力!E17) -> 1 | F16: =入力!F17 -> 1100 | G16: =IF(入力!E17="","",入力!G17) -> 100 | H16: =入力!H17 -> 1100 | I16: =IF(入力!I17="","",入力!I17)
C17: 図面類 | E17: =IF(入力!E18="","",入力!E18) -> 3 | F17: =入力!F18 -> 1100 | G17: =IF(入力!E18="","",入力!G18) -> 100 | H17: =入力!H18 -> 3300 | I17: =IF(入力!I18="","",入力!I18)
C18: 疎明書面 | E18: =IF(入力!E19="","",入力!E19) -> 1 | F18: =入力!F19 -> 6000 | G18: =IF(入力!E19="","",入力!G19) -> 100 | H18: =入力!H19 -> 6000 | I18: =IF(入力!I19="","",入力!I19)
B19: 現 地 | C19: 確認 | E19: =IF(入力!E20="","",入力!E20) | F19: =入力!F20 -> 8000 | G19: =IF(入力!E20="","",入力!G20) | H19: =入力!H20 | I19: =IF(入力!I20="","",入力!I20) -> 敷地境界が不明な場合の調査
C20: 探索 | E20: =IF(入力!E21="","",入力!E21) | F20: =入力!F21 -> 10000 | G20: =IF(入力!E21="","",入力!G21) | H20: =入力!H21 | I20: =IF(入力!I21="","",入力!I21) -> 敷地境界が不明な場合の調査
C21: 多角測量 | E21: =IF(入力!E22="","",入力!E22) | F21: 15000 | G21: =IF(入力!E22="","",入力!G22) | H21: =入力!H22 | I21: =IF(入力!I22="","",入力!I22) -> 敷地境界が不明な場合の調査
G22: 小 計 | H22: =入力!H23 -> 13700 | I22: =IF(入力!I23="","",入力!I23)
A23: 測量業務 | B23: =IF(入力!B24="","",入力!B24) -> 面積測量 | E23: =IF(入力!E24="","",入力!E24) -> 110 | F23: =入力!F24 -> 40000 | G23: =IF(入力!E24="","",入力!G24) -> 100 | H23: =入力!H24 -> 40000 | I23: =IF(入力!I24="","",入力!I24)
B24: =IF(入力!B25="","",入力!B25) | E24: =IF(入力!E25="","",入力!E25) | F24: =入力!F25 | G24: =IF(入力!E25="","",入力!G25) | H24: =入力!H25 | I24: =IF(入力!I25="","",入力!I25)
B25: =IF(入力!B26="","",入力!B26) | E25: =IF(入力!E26="","",入力!E26) | F25: =入力!F26 | G25: =IF(入力!E26="","",入力!G26) | H25: =入力!H26 | I25: =IF(入力!I26="","",入力!I26)
B26: =IF(入力!B27="","",入力!B27) | E26: =IF(入力!E27="","",入力!E27) | F26: =入力!F27 | G26: =IF(入力!E27="","",入力!G27) | H26: =入力!H27 | I26: =IF(入力!I27="","",入力!I27)
G27: 小 計 | H27: =入力!H28 -> 40000 | I27: =IF(入力!I28="","",入力!I28)
A28: 登記申請業務 | B28: =入力!B29 -> 表題 | D28: 基本 | E28: =IF(入力!E29="","",入力!E29) -> 1 | F28: =入力!F29 -> 25000 | G28: =IF(入力!E29+入力!E30+入力!E31=0,"",入力!G29) -> 100 | H28: =入力!H29 -> 30000 | I28: =IF(入力!I29="","",入力!I29) -> 1棟1階
D29: 加算 | E29: =IF(入力!E30="","",入力!E30) | F29: =入力!F30 -> 6000 | I29: =IF(入力!I30="","",入力!I30) -> 附属建物1棟1階増加ごと
D30: 加算 | E30: =IF(入力!E31="","",入力!E31) -> 1 | F30: =入力!F31 -> 5000 | I30: =IF(入力!I31="","",入力!I31) -> 1階増加ごと
B31: =入力!B32 -> 表示変更・更正 | D31: 基本 | E31: =IF(入力!E32="","",入力!E32) | F31: =入力!F32 -> 25000 | G31: =IF(入力!E32+入力!E33+入力!E34=0,"",入力!G32) | H31: =入力!H32 | I31: =IF(入力!I32="","",入力!I32) -> 1棟1階
D32: 加算 | E32: =IF(入力!E33="","",入力!E33) | F32: =入力!F33 -> 6000 | I32: =IF(入力!I33="","",入力!I33) -> 附属建物1棟1階増加ごと
D33: 加算 | E33: =IF(入力!E34="","",入力!E34) | F33: =入力!F34 -> 5000 | I33: =IF(入力!I34="","",入力!I34) -> 1階増加ごと
B34: =入力!B35 -> 表示変更・更正 （図面不要） | D34: 基本 | E34: =IF(入力!E35="","",入力!E35) | F34: =入力!F35 -> 20000 | G34: =IF(入力!E35+入力!E36=0,"",入力!G35) | H34: =入力!H35 | I34: =IF(入力!I35="","",入力!I35) -> 1棟
D35: 加算 | E35: =IF(入力!E36="","",入力!E36) | F35: =入力!F36 -> 1000 | I35: =IF(入力!I36="","",入力!I36) -> 附属建物1棟増加ごと
B36: =入力!B37 -> 滅失 | D36: 基本 | E36: =IF(入力!E37="","",入力!E37) | F36: =入力!F37 -> 20000 | G36: =IF(入力!E37+入力!E38=0,"",入力!G37) | H36: =入力!H37 | I36: =IF(入力!I37="","",入力!I37) -> 1棟
D37: 加算 | E37: =IF(入力!E38="","",入力!E38) | F37: =入力!F38 -> 1000 | I37: =IF(入力!I38="","",入力!I38) -> 附属建物1棟増加ごと
B38: =IF(入力!B39="","",入力!B39) | D38: 基本 | E38: =IF(入力!E39="","",入力!E39) | F38: =入力!F39 -> 15000 | G38: =IF(入力!E39+入力!E40+入力!E41+入力!E42+入力!E43=0,"",入力!G39) | H38: =入力!H39 | I38: =IF(入力!I39="","",入力!I39)
D39: 加算 | E39: =IF(入力!E40="","",入力!E40) | F39: =入力!F40 -> 0 | I39: =IF(入力!I40="","",入力!I40)
D40: 加算 | E40: =IF(入力!E41="","",入力!E41) | F40: =入力!F41 -> 0 | I40: =IF(入力!I41="","",入力!I41)
D41: 加算 | E41: =IF(入力!E42="","",入力!E42) | F41: =入力!F42 -> 0 | I41: =IF(入力!I42="","",入力!I42)
D42: 加算 | E42: =IF(入力!E43="","",入力!E43) | F42: =入力!F43 -> 0 | I42: =IF(入力!I43="","",入力!I43)
...

Sheet 領収書
A7: =IF(入力!I10="","",入力!I10) | G7: =IF(入力!I9="","領収日 令和 年 月 日",入力!I9) -> 46080
A9: =IF(入力!I11="","",入力!I11) -> 玉腰裕規様、明日野様 | G9: 事務所 豊橋市前田南町一丁目1番地5
B10: 下記のとおり領収いたしました。 | G10: ﾀﾜｰﾚｼﾞﾃﾞﾝｽｱﾈｯｸｽ2-2E
B11: =入力!I12 -> 133870 | G11: =入力!I4 -> 山本真基
A12: 所 在 | E12: =IF(入力!E13="","",入力!E13) -> 浜松中央区初生町822番20、822番23、822番25
A13: 受 託 内 容 | E13: =IF(入力!E14="","",入力!E14) -> 建物表題登記
A14: 作 業 種 別 | E14: 数 量 | F14: 基 準 額 | G14: 加減率等 | H14: 報 酬 額 | I14: 摘 要
A15: 調査業務 | B15: 資料 | C15: 公簿類 | E15: =IF(入力!E16="","",入力!E16) -> 3 | F15: =入力!F16 -> 1100 | G15: =IF(入力!E16="","",入力!G16) -> 100 | H15: =入力!H16 -> 3300 | I15: =IF(入力!I16="","",入力!I16)
C16: 地図類 | E16: =IF(入力!E17="","",入力!E17) -> 1 | F16: =入力!F17 -> 1100 | G16: =IF(入力!E17="","",入力!G17) -> 100 | H16: =入力!H17 -> 1100 | I16: =IF(入力!I17="","",入力!I17)
C17: 図面類 | E17: =IF(入力!E18="","",入力!E18) -> 3 | F17: =入力!F18 -> 1100 | G17: =IF(入力!E18="","",入力!G18) -> 100 | H17: =入力!H18 -> 3300 | I17: =IF(入力!I18="","",入力!I18)
C18: 疎明書面 | E18: =IF(入力!E19="","",入力!E19) -> 1 | F18: =入力!F19 -> 6000 | G18: =IF(入力!E19="","",入力!G19) -> 100 | H18: =入力!H19 -> 6000 | I18: =IF(入力!I19="","",入力!I19)
B19: 現 地 | C19: 確認 | E19: =IF(入力!E20="","",入力!E20) | F19: =入力!F20 -> 8000 | G19: =IF(入力!E20="","",入力!G20) | H19: =入力!H20 | I19: =IF(入力!I20="","",入力!I20) -> 敷地境界が不明な場合の調査
C20: 探索 | E20: =IF(入力!E21="","",入力!E21) | F20: =入力!F21 -> 10000 | G20: =IF(入力!E21="","",入力!G21) | H20: =入力!H21 | I20: =IF(入力!I21="","",入力!I21) -> 敷地境界が不明な場合の調査
C21: 多角測量 | E21: =IF(入力!E22="","",入力!E22) | F21: 15000 | G21: =IF(入力!E22="","",入力!G22) | H21: =入力!H22 | I21: =IF(入力!I22="","",入力!I22) -> 敷地境界が不明な場合の調査
G22: 小 計 | H22: =入力!H23 -> 13700 | I22: =IF(入力!I23="","",入力!I23)
A23: 測量業務 | B23: =IF(入力!B24="","",入力!B24) -> 面積測量 | E23: =IF(入力!E24="","",入力!E24) -> 110 | F23: =入力!F24 -> 40000 | G23: =IF(入力!E24="","",入力!G24) -> 100 | H23: =入力!H24 -> 40000 | I23: =IF(入力!I24="","",入力!I24)
B24: =IF(入力!B25="","",入力!B25) | E24: =IF(入力!E25="","",入力!E25) | F24: =入力!F25 | G24: =IF(入力!E25="","",入力!G25) | H24: =入力!H25 | I24: =IF(入力!I25="","",入力!I25)
B25: =IF(入力!B26="","",入力!B26) | E25: =IF(入力!E26="","",入力!E26) | F25: =入力!F26 | G25: =IF(入力!E26="","",入力!G26) | H25: =入力!H26 | I25: =IF(入力!I26="","",入力!I26)
B26: =IF(入力!B27="","",入力!B27) | E26: =IF(入力!E27="","",入力!E27) | F26: =入力!F27 | G26: =IF(入力!E27="","",入力!G27) | H26: =入力!H27 | I26: =IF(入力!I27="","",入力!I27)
G27: 小 計 | H27: =入力!H28 -> 40000 | I27: =IF(入力!I28="","",入力!I28)
A28: 登記申請業務 | B28: =入力!B29 -> 表題 | D28: 基本 | E28: =IF(入力!E29="","",入力!E29) -> 1 | F28: =入力!F29 -> 25000 | G28: =IF(入力!E29+入力!E30+入力!E31=0,"",入力!G29) -> 100 | H28: =入力!H29 -> 30000 | I28: =IF(入力!I29="","",入力!I29) -> 1棟1階
D29: 加算 | E29: =IF(入力!E30="","",入力!E30) | F29: =入力!F30 -> 6000 | I29: =IF(入力!I30="","",入力!I30) -> 附属建物1棟1階増加ごと
D30: 加算 | E30: =IF(入力!E31="","",入力!E31) -> 1 | F30: =入力!F31 -> 5000 | I30: =IF(入力!I31="","",入力!I31) -> 1階増加ごと
B31: =入力!B32 -> 表示変更・更正 | D31: 基本 | E31: =IF(入力!E32="","",入力!E32) | F31: =入力!F32 -> 25000 | G31: =IF(入力!E32+入力!E33+入力!E34=0,"",入力!G32) | H31: =入力!H32 | I31: =IF(入力!I32="","",入力!I32) -> 1棟1階
D32: 加算 | E32: =IF(入力!E33="","",入力!E33) | F32: =入力!F33 -> 6000 | I32: =IF(入力!I33="","",入力!I33) -> 附属建物1棟1階増加ごと
D33: 加算 | E33: =IF(入力!E34="","",入力!E34) | F33: =入力!F34 -> 5000 | I33: =IF(入力!I34="","",入力!I34) -> 1階増加ごと
B34: =入力!B35 -> 表示変更・更正 （図面不要） | D34: 基本 | E34: =IF(入力!E35="","",入力!E35) | F34: =入力!F35 -> 20000 | G34: =IF(入力!E35+入力!E36=0,"",入力!G35) | H34: =入力!H35 | I34: =IF(入力!I35="","",入力!I35) -> 1棟
D35: 加算 | E35: =IF(入力!E36="","",入力!E36) | F35: =入力!F36 -> 1000 | I35: =IF(入力!I36="","",入力!I36) -> 附属建物1棟増加ごと
B36: =入力!B37 -> 滅失 | D36: 基本 | E36: =IF(入力!E37="","",入力!E37) | F36: =入力!F37 -> 20000 | G36: =IF(入力!E37+入力!E38=0,"",入力!G37) | H36: =入力!H37 | I36: =IF(入力!I37="","",入力!I37) -> 1棟
D37: 加算 | E37: =IF(入力!E38="","",入力!E38) | F37: =入力!F38 -> 1000 | I37: =IF(入力!I38="","",入力!I38) -> 附属建物1棟増加ごと
B38: =IF(入力!B39="","",入力!B39) | D38: 基本 | E38: =IF(入力!E39="","",入力!E39) | F38: =入力!F39 -> 15000 | G38: =IF(入力!E39+入力!E40+入力!E41+入力!E42+入力!E43=0,"",入力!G39) | H38: =入力!H39 | I38: =IF(入力!I39="","",入力!I39)
D39: 加算 | E39: =IF(入力!E40="","",入力!E40) | F39: =入力!F40 -> 0 | I39: =IF(入力!I40="","",入力!I40)
D40: 加算 | E40: =IF(入力!E41="","",入力!E41) | F40: =入力!F41 -> 0 | I40: =IF(入力!I41="","",入力!I41)
D41: 加算 | E41: =IF(入力!E42="","",入力!E42) | F41: =入力!F42 -> 0 | I41: =IF(入力!I42="","",入力!I42)
D42: 加算 | E42: =IF(入力!E43="","",入力!E43) | F42: =入力!F43 -> 0 | I42: =IF(入力!I43="","",入力!I43)
B43: =入力!B44 -> 現地調査費 | E43: =IF(入力!E44="","",入力!E44) -> 1 | F43: =入力!F44 -> 18000 | G43: =IF(入力!E44="","",入力!G44) -> 100 | H43: =入力!H44 -> 18000 | I43: =IF(入力!I44="","",入力!I44)
G44: 小 計 | H44: =入力!H45 -> 48000 | I44: =IF(入力!I45="","",入力!I45)
A45: 書類作成等 | B45: =入力!B46 -> 調査報告書 | E45: =IF(入力!E46="","",入力!E46) -> 1 | F45: =入力!F46 -> 6000 | G45: =IF(入力!E46="","",入力!G46) -> 100 | H45: =入力!H46 -> 6000 | I45: =IF(入力!I46="","",入力!I46)
B46: =入力!B47 -> 原本の複製 | E46: =IF(入力!E47="","",入力!E47) -> 4 | F46: =入力!F47 -> 1000 | G46: =IF(入力!E47="","",入力!G47) -> 100 | H46: =入力!H47 -> 4000 | I46: =IF(入力!I47="","",入力!I47)
B47: =入力!B48 -> 工事完了引渡証明 | E47: =IF(入力!E48="","",入力!E48) -> 1 | F47: =入力!F48 -> 5000 | G47: =IF(入力!E48="","",入力!G48) -> 100 | H47: =入力!H48 -> 5000 | I47: =IF(入力!I48="","",入力!I48)
...

Sheet 請求書・領収書(控)
G5: =IF(入力!I8="","請求日",入力!I8) -> 46058
A7: =IF(入力!I10="","",入力!I10) | G7: =IF(入力!I9="","領収日 令和 年 月 日",入力!I9) -> 46080
A9: =IF(入力!I11="","",入力!I11) -> 玉腰裕規様、明日野様 | G9: 事務所 豊橋市前田南町一丁目1番地5
G10: ﾀﾜｰﾚｼﾞﾃﾞﾝｽｱﾈｯｸｽ2-2E
B11: =入力!I12 -> 133870 | G11: =入力!I4 -> 山本真基
A12: 所 在 | E12: =IF(入力!E13="","",入力!E13) -> 浜松中央区初生町822番20、822番23、822番25
A13: 受 託 内 容 | E13: =IF(入力!E14="","",入力!E14) -> 建物表題登記
A14: 作 業 種 別 | E14: 数 量 | F14: 基 準 額 | G14: 加減率等 | H14: 報 酬 額 | I14: 摘 要
A15: 調査業務 | B15: 資料 | C15: 公簿類 | E15: =IF(入力!E16="","",入力!E16) -> 3 | F15: =入力!F16 -> 1100 | G15: =IF(入力!E16="","",入力!G16) -> 100 | H15: =入力!H16 -> 3300 | I15: =IF(入力!I16="","",入力!I16)
C16: 地図類 | E16: =IF(入力!E17="","",入力!E17) -> 1 | F16: =入力!F17 -> 1100 | G16: =IF(入力!E17="","",入力!G17) -> 100 | H16: =入力!H17 -> 1100 | I16: =IF(入力!I17="","",入力!I17)
C17: 図面類 | E17: =IF(入力!E18="","",入力!E18) -> 3 | F17: =入力!F18 -> 1100 | G17: =IF(入力!E18="","",入力!G18) -> 100 | H17: =入力!H18 -> 3300 | I17: =IF(入力!I18="","",入力!I18)
C18: 疎明書面 | E18: =IF(入力!E19="","",入力!E19) -> 1 | F18: =入力!F19 -> 6000 | G18: =IF(入力!E19="","",入力!G19) -> 100 | H18: =入力!H19 -> 6000 | I18: =IF(入力!I19="","",入力!I19)
B19: 現 地 | C19: 確認 | E19: =IF(入力!E20="","",入力!E20) | F19: =入力!F20 -> 8000 | G19: =IF(入力!E20="","",入力!G20) | H19: =入力!H20 | I19: =IF(入力!I20="","",入力!I20) -> 敷地境界が不明な場合の調査
C20: 探索 | E20: =IF(入力!E21="","",入力!E21) | F20: =入力!F21 -> 10000 | G20: =IF(入力!E21="","",入力!G21) | H20: =入力!H21 | I20: =IF(入力!I21="","",入力!I21) -> 敷地境界が不明な場合の調査
C21: 多角測量 | E21: =IF(入力!E22="","",入力!E22) | F21: 15000 | G21: =IF(入力!E22="","",入力!G22) | H21: =入力!H22 | I21: =IF(入力!I22="","",入力!I22) -> 敷地境界が不明な場合の調査
G22: 小 計 | H22: =入力!H23 -> 13700 | I22: =IF(入力!I23="","",入力!I23)
A23: 測量業務 | B23: =IF(入力!B24="","",入力!B24) -> 面積測量 | E23: =IF(入力!E24="","",入力!E24) -> 110 | F23: =入力!F24 -> 40000 | G23: =IF(入力!E24="","",入力!G24) -> 100 | H23: =入力!H24 -> 40000 | I23: =IF(入力!I24="","",入力!I24)
B24: =IF(入力!B25="","",入力!B25) | E24: =IF(入力!E25="","",入力!E25) | F24: =入力!F25 | G24: =IF(入力!E25="","",入力!G25) | H24: =入力!H25 | I24: =IF(入力!I25="","",入力!I25)
B25: =IF(入力!B26="","",入力!B26) | E25: =IF(入力!E26="","",入力!E26) | F25: =入力!F26 | G25: =IF(入力!E26="","",入力!G26) | H25: =入力!H26 | I25: =IF(入力!I26="","",入力!I26)
B26: =IF(入力!B27="","",入力!B27) | E26: =IF(入力!E27="","",入力!E27) | F26: =入力!F27 | G26: =IF(入力!E27="","",入力!G27) | H26: =入力!H27 | I26: =IF(入力!I27="","",入力!I27)
G27: 小 計 | H27: =入力!H28 -> 40000 | I27: =IF(入力!I28="","",入力!I28)
A28: 登記申請業務 | B28: =入力!B29 -> 表題 | D28: 基本 | E28: =IF(入力!E29="","",入力!E29) -> 1 | F28: =入力!F29 -> 25000 | G28: =IF(入力!E29+入力!E30+入力!E31=0,"",入力!G29) -> 100 | H28: =入力!H29 -> 30000 | I28: =IF(入力!I29="","",入力!I29) -> 1棟1階
D29: 加算 | E29: =IF(入力!E30="","",入力!E30) | F29: =入力!F30 -> 6000 | I29: =IF(入力!I30="","",入力!I30) -> 附属建物1棟1階増加ごと
D30: 加算 | E30: =IF(入力!E31="","",入力!E31) -> 1 | F30: =入力!F31 -> 5000 | I30: =IF(入力!I31="","",入力!I31) -> 1階増加ごと
B31: =入力!B32 -> 表示変更・更正 | D31: 基本 | E31: =IF(入力!E32="","",入力!E32) | F31: =入力!F32 -> 25000 | G31: =IF(入力!E32+入力!E33+入力!E34=0,"",入力!G32) | H31: =入力!H32 | I31: =IF(入力!I32="","",入力!I32) -> 1棟1階
D32: 加算 | E32: =IF(入力!E33="","",入力!E33) | F32: =入力!F33 -> 6000 | I32: =IF(入力!I33="","",入力!I33) -> 附属建物1棟1階増加ごと
D33: 加算 | E33: =IF(入力!E34="","",入力!E34) | F33: =入力!F34 -> 5000 | I33: =IF(入力!I34="","",入力!I34) -> 1階増加ごと
B34: =入力!B35 -> 表示変更・更正 （図面不要） | D34: 基本 | E34: =IF(入力!E35="","",入力!E35) | F34: =入力!F35 -> 20000 | G34: =IF(入力!E35+入力!E36=0,"",入力!G35) | H34: =入力!H35 | I34: =IF(入力!I35="","",入力!I35) -> 1棟
D35: 加算 | E35: =IF(入力!E36="","",入力!E36) | F35: =入力!F36 -> 1000 | I35: =IF(入力!I36="","",入力!I36) -> 附属建物1棟増加ごと
B36: =入力!B37 -> 滅失 | D36: 基本 | E36: =IF(入力!E37="","",入力!E37) | F36: =入力!F37 -> 20000 | G36: =IF(入力!E37+入力!E38=0,"",入力!G37) | H36: =入力!H37 | I36: =IF(入力!I37="","",入力!I37) -> 1棟
D37: 加算 | E37: =IF(入力!E38="","",入力!E38) | F37: =入力!F38 -> 1000 | I37: =IF(入力!I38="","",入力!I38) -> 附属建物1棟増加ごと
B38: =IF(入力!B39="","",入力!B39) | D38: 基本 | E38: =IF(入力!E39="","",入力!E39) | F38: =入力!F39 -> 15000 | G38: =IF(入力!E39+入力!E40+入力!E41+入力!E42+入力!E43=0,"",入力!G39) | H38: =入力!H39 | I38: =IF(入力!I39="","",入力!I39)
D39: 加算 | E39: =IF(入力!E40="","",入力!E40) | F39: =入力!F40 -> 0 | I39: =IF(入力!I40="","",入力!I40)
D40: 加算 | E40: =IF(入力!E41="","",入力!E41) | F40: =入力!F41 -> 0 | I40: =IF(入力!I41="","",入力!I41)
D41: 加算 | E41: =IF(入力!E42="","",入力!E42) | F41: =入力!F42 -> 0 | I41: =IF(入力!I42="","",入力!I42)
D42: 加算 | E42: =IF(入力!E43="","",入力!E43) | F42: =入力!F43 -> 0 | I42: =IF(入力!I43="","",入力!I43)
B43: =入力!B44 -> 現地調査費 | E43: =IF(入力!E44="","",入力!E44) -> 1 | F43: =入力!F44 -> 18000 | G43: =IF(入力!E44="","",入力!G44) -> 100 | H43: =入力!H44 -> 18000 | I43: =IF(入力!I44="","",入力!I44)
G44: 小 計 | H44: =入力!H45 -> 48000 | I44: =IF(入力!I45="","",入力!I45)
A45: 書類作成等 | B45: =入力!B46 -> 調査報告書 | E45: =IF(入力!E46="","",入力!E46) -> 1 | F45: =入力!F46 -> 6000 | G45: =IF(入力!E46="","",入力!G46) -> 100 | H45: =入力!H46 -> 6000 | I45: =IF(入力!I46="","",入力!I46)
B46: =入力!B47 -> 原本の複製 | E46: =IF(入力!E47="","",入力!E47) -> 4 | F46: =入力!F47 -> 1000 | G46: =IF(入力!E47="","",入力!G47) -> 100 | H46: =入力!H47 -> 4000 | I46: =IF(入力!I47="","",入力!I47)
...
